#csharp图解编程  #csharp学习 #学习笔记 

# 1 什么是异常

异常是程序中的运行时错误，它违反了系统约束或应用程序约束，或出现了在正常操作时未预料的情形。


# 2 异常捕获

## 2.1 try语句

try语句用来指明为避免出现异常而被保护的代码段，并在发生异常时提供代码处理异常。try语句由3个部分组成，
1. try 块包含为避免出现异常而被保护的代码
2. catch 子句部分含有一个或多个catch子句。这些是处理异常的代码段，它们也称为是异常处理程序
3. finally 块含有在所有情况下都要被执行的代码，无论有没有异常发生

## 2.2 异常类

有许多不同类型的异常可以在程序中发生。BCL定义了许多类，每一个类代表一个指定的异常类型。当一个异常发生时，CLR:
1. 创建该类型的异常对象
2. 寻找适当的catch子句以处理它

异常类中的属性
| 属性           | 类型      | 描述                   |
| -------------- | --------- | ---------------------- |
| Message        | string    | 解释异常原因的消息     |
| StackTrace     | string    | 发生在何处             |
| InnerException | Exception | 前一个异常的引用       |
| HelpLink       | string    | 为异常原因提供URN或URL |
| Source         | string    | 异常所在程序集的名称   | 

## 2.3 catch子句
```csharp
catch {}
catch (ExceptionType) {}
catch (ExceptionType e) {}
```

1. 一般catch子句能接受任何异常，但不能确定引发异常的类型。这只允许对任何可能发生的异常的普通处理和清理。
2. 特定catch子句形式把一个异常类的名称作为参数。它匹配该指定类或派生自它的异常类的异常。
3. 带对象的特定catch子句提供关于异常的最多信息。它匹配该指定类的异常，或派生自它的异常类的异常。
```csharp
int x=10;
try
{
    int y=0;
    x/=y;
}
catch(DivideByZeroException e)
{
    Console.WriteLine("Message: {0}",e.Message);
    Console.WriteLine("Source:  {0}",e.Source);
    Console.WriteLine("Stack:   {0}",e.StackTrace);
}
```

## 2.4 catch子句段

当异常发生时，系统按顺序搜索catch子句的列表，第一个匹配该异常对象类型的catch子句被执行。因此，catch子句的排序有两个重要的规则。具体如下。

1. 特定catch子句必须以一种顺序排列，最明确的异常类型第一，直到最普通的类型。例如，如果声明了一个派生自NullReferenceException的异常类，那么派生异常类型的catch子句应该被列在NullReferenceException的catch子句之前
2. 如果有一个一般catch子句，它必须是最后一个，并且在所有特定catch子句之后。不鼓励使用一般catch子句.因为它允许程序继续执行隐藏错误，让程序处于一种未知的状态。应尽可能使用特定catch子句

## 2.5 finally块

如果程序的控制流进人了一个带finally块的try语句，那么finally始终会被执行。

1. 如果在try块内部没有异常发生，那么在try块的结尾，控制流跳过任何catch子句并到finally块
2. 如果在try块内部发生了异常，那么在catch子句段中无论哪一个适当的catch子句被执行，接着就是finally块的执行

# 3 抛出异常
可以使用throw语句使代码显式地引发一个异常。throw语句的语法`throw ExceptionObject;`

eg:

```csharp
class MyClass
{
    public static void PrintArg(string arg)
    {
        try
        {
            if(arg==null)
            {
                var myEx=new ArgumentNullException("arg");
                throw myEx;
            }
            Console.WriteLine(arg);
        }
        catch(ArgumentNullException e)
        {
            Console.WriteLine("Message:  {0}",e.Message);
        }
    }
}
class Program
{
    static void Main()
    {
        string s=null;
        MyClass.PrintArg(s);
        MyClass.PrintArg("Hi there!");
    }
}
```

## 3,1 不带异常对象的抛出

throw语句还可以不带异常对象使用，在catch块内部。

1. 这种形式重新抛出当前异常，系统继续它的搜索，为该异常寻找另外的处理代码
2. 这种形式只能用在catch语句内部

eg:
```csharp
class MyClass
{
    public static void PrintArg(string arg)
    {
        try
        {
            try
            {
                if(arg==null)
                {
                    var myEx=new ArgumentNullException("arg");
                    throw myEx;
                }
                Console.WriteLine(arg);
            }
            catch(ArgumentNullException e)
            {
                Console.WriteLine("Inner Catch:  {0}",e.Message);
                throw;
            }
        }
        catch
        {
            Console.WriteLine("Outer Catch:  Handling an Exception.");
        }
    }
}
class Program
{
    static void Main()
    {
        string s=null;
        MyClass.PrintArg(s);
    }
}
```